Workbook

Sheet Summary
A1: nutrifitness.ch – Product catalogue audit (WooCommerce export of 4 Oct 2026)
A2: Source: uploaded CSV. 243 rows = 105 parent products + 138 variations. Counts below are live formulas over the "Catalogue" sheet.
A4: Check | B4: Products | C4: % of 105 | D4: Why it matters
A5: Total parent products | B5: =COUNTA(Catalogue!$A$2:$A$106) -> 105 | D5: Baseline
A6: ALL CAPS names | B6: =COUNTIF(Catalogue!$O$2:$O$106,"*ALL CAPS name*") -> 101 | C6: =B6/$B$5 -> 0.96190476 | D6: Hard to read, looks unpolished in results; also mismatches how people search
A7: Brand missing from product name (before rewrite) | B7: 86 | C7: =B7/$B$5 -> 0.81904762 | D7: Hardcoded from the original CSV: only 15 of 101 branded products had the brand in the name, so 86 lacked it.
A8: Brand not set in WooCommerce | B8: =COUNTIF(Catalogue!$H$2:$H$106,"— missing —") -> 4 | C8: =B8/$B$5 -> 0.038095238 | D8: Missing brand hurts Shopping eligibility and brand-page SEO
A9: Unpublished products | B9: =COUNTIF(Catalogue!$N$2:$N$106,"No") -> 8 | C9: =B9/$B$5 -> 0.076190476 | D9: Includes pre-workout lines: check whether intentional
A10: Empty short description | B10: =COUNTIF(Catalogue!$O$2:$O$106,"*Empty short*") -> 4 | C10: =B10/$B$5 -> 0.038095238 | D10: Short description sits next to the buy button
A11: Empty long description | B11: =COUNTIF(Catalogue!$O$2:$O$106,"*Empty long*") -> 1 | C11: =B11/$B$5 -> 0.0095238095 | D11: No content = nothing to rank
A12: H1 inside long description | B12: =COUNTIF(Catalogue!$O$2:$O$106,"*H1 inside*") -> 36 | C12: =B12/$B$5 -> 0.34285714 | D12: Second H1 on the page confuses structure
A13: Instagram link inside body text | B13: =COUNTIF(Catalogue!$O$2:$O$106,"*Instagram link*") -> 77 | C13: =B13/$B$5 -> 0.73333333 | D13: Sends visitors away from the product page; use internal links instead
A14: Pasted HTML junk (editor classes / data attributes) | B14: =COUNTIF(Catalogue!$O$2:$O$106,"*Pasted HTML*") -> 55 | C14: =B14/$B$5 -> 0.52380952 | D14: Bloats pages, can break styling and structured text
A15: Descriptions with health-claim words | B15: =COUNTIF(Catalogue!$L$2:$L$106,"?*") -> 52 | C15: =B15/$B$5 -> 0.4952381 | D15: Swiss food rules limit health claims: client must review
A16: Claim-style product names | B16: =COUNTIF(Catalogue!$K$2:$K$106,"?*") -> 7 | C16: =B16/$B$5 -> 0.066666667 | D16: Names like "Diurétique" or "Cholesterol Support" are claims
A17: Needs category correction | B17: =COUNTIF(Catalogue!$J$2:$J$106,"?*") -> 13 | C17: =B17/$B$5 -> 0.12380952 | D17: Wrong categories dilute topical relevance
A18: Variable products with GTIN gaps | B18: =COUNTIF(Catalogue!$M$2:$M$106,"*missing*") -> 21 | C18: =B18/$B$5 -> 0.2 | D18: GTIN is strongly recommended for Merchant Center
A19: Simple products without GTIN | B19: =COUNTIF(Catalogue!$M$2:$M$106,"Missing") -> 10 | C19: =B19/$B$5 -> 0.095238095 | D19: Same
A21: Other findings
A22: • 51 of 105 products sit in "NOS BEST-SELLERS" – the label loses meaning and dilutes category pages. Keep it for ~8–12 real best sellers.
A23: • Duplicate category trees: "PERTE DE POIDS" and "COMPLÉMENTS > PERTE DE POIDS & MÉTABOLISME" (and the same for PROTÉINES) – merge into one hierarchy before the Next.js migration.
A24: • Several products carry 4–5 categories; choose one primary category per product for breadcrumbs and canonical structure.
A25: • Draft names follow: Product type + variant + size – Brand. Names are drafts: confirm unclear products (Enerdyn, Beebad, UFO Blast, Calibration, Recharge, Stage, HBVC) against the supplier label.
A26: • Meta titles are drafts; rows over 60 characters are highlighted red.
A27: • Nothing here uses facts that are not in the current export. Every unknown is marked [À VÉRIFIER].

Sheet Catalogue
A1: ID | B1: Type | C1: Current name | D1: NEW name (draft) | E1: New name length | F1: Meta title (draft) | G1: Meta length | H1: Brand | I1: Current categories | J1: Category fix | K1: Claim risk in name | L1: Claim words found in text | M1: GTIN status | N1: Published | O1: Issues found
A2: 7854 | B2: simple | C2: PW CREAPURE PREMIUM 250G | D2: Créatine Creapure® Premium 250 g – Powerfood | E2: =LEN(D2) -> 44 | F2: Créatine Creapure® Premium 250 g – Powerfood | Nutrifitness | G2: =LEN(F2) -> 59 | H2: Powerfood | I2: APRES SPORT, CRÉATINE | L2: alzheimer, parkinson | M2: Missing | N2: Yes | O2: ALL CAPS name
A3: 7870 | B3: simple | C3: GALLON NF 2.2L | D3: Gourde Gallon 2,2 L – Nutrifit | E3: =LEN(D3) -> 30 | F3: Gourde Gallon 2,2 L – Nutrifit | Nutrifitness | G3: =LEN(F3) -> 45 | H3: Nutrifit | I3: ACCESSOIRES, SHAKERS | M3: Missing | N3: Yes | O3: ALL CAPS name
A4: 7890 | B4: simple | C4: VITAMINE C LIPOSOMALE 60 CAPS | D4: Vitamine C liposomale 60 gélules – Pronutrition | E4: =LEN(D4) -> 47 | F4: Vitamine C liposomale 60 gélules – Pronutrition | G4: =LEN(F4) -> 47 | H4: Pronutrition | I4: VITAMINES - MINÉRAUX | L4: immunitaire | M4: OK | N4: Yes | O4: Instagram link in body; ALL CAPS name
A5: 7901 | B5: simple | C5: PICOLINATE DE CHROME 100 CAPS | D5: Picolinate de chrome 100 gélules – Pronutrition | E5: =LEN(D5) -> 47 | F5: Picolinate de chrome 100 gélules – Pronutrition | G5: =LEN(F5) -> 47 | H5: Pronutrition | I5: PERTE DE POIDS, COMPLÉMENTS > PERTE DE POIDS & MÉTABOLISME | L5: cholestérol, diabète, perte de poids | M5: OK | N5: Yes | O5: Instagram link in body; ALL CAPS name
A6: 8857 | B6: simple | C6: CAFFEINE 90 CAPS 100MG | D6: Caféine 100 mg – 90 gélules – Bigman | E6: =LEN(D6) -> 36 | F6: Caféine 100 mg – 90 gélules – Bigman | Nutrifitness | G6: =LEN(F6) -> 51 | H6: Bigman | I6: AVANT SPORT, NOS BEST-SELLERS | L6: soigne | M6: OK | N6: Yes | O6: Instagram link in body; ALL CAPS name
A7: 8867 | B7: simple | C7: ASHWAGANDHA 60 CAPS | D7: Ashwagandha 60 gélules – Pronutrition | E7: =LEN(D7) -> 37 | F7: Ashwagandha 60 gélules – Pronutrition | Nutrifitness | G7: =LEN(F7) -> 52 | H7: Pronutrition | I7: SOMMEIL, VITAMINES - MINÉRAUX | L7: hormon | M7: OK | N7: Yes | O7: ALL CAPS name
A8: 8942 | B8: simple | C8: BLANC D'OEUF LIQUIDE PASTEURISÉ 1L | D8: Blanc d'œuf liquide pasteurisé 1 L – Eurovo | E8: =LEN(D8) -> 43 | F8: Blanc d'œuf liquide pasteurisé 1 L – Eurovo | Nutrifitness | G8: =LEN(F8) -> 58 | H8: Eurovo | I8: SHAKERS | J8: Listed under SHAKERS – move to a food/ingredients category | M8: OK | N8: Yes | O8: Instagram link in body; ALL CAPS name
A9: 9378 | B9: variable | C9: SAVIOR RECUPERATION 950G | D9: Savior Récupération 950 g – Marvelous | E9: =LEN(D9) -> 37 | F9: Savior Récupération 950 g – Marvelous | Nutrifitness | G9: =LEN(F9) -> 52 | H9: Marvelous | I9: APRES SPORT, CRÉATINE, PENDANT SPORT | M9: OK (all variations) | N9: Yes | O9: Instagram link in body; ALL CAPS name
A10: 9526 | B10: simple | C10: CREATINE EN POUDRE 300G | D10: Créatine 200 mesh en poudre 300 g – Marvelous | E10: =LEN(D10) -> 45 | F10: Créatine 200 mesh en poudre 300 g – Marvelous | Nutrifitness | G10: =LEN(F10) -> 60 | H10: Marvelous | I10: APRES SPORT, CRÉATINE, NOS BEST-SELLERS | L10: alzheimer, jusqu'à 10, parkinson | M10: OK | N10: Yes | O10: Instagram link in body; ALL CAPS name
A11: 9616 | B11: variable | C11: NF SHAKER 600ML | D11: Shaker NF 600 ml – Nutrifit | E11: =LEN(D11) -> 27 | F11: Shaker NF 600 ml – Nutrifit | Nutrifitness | G11: =LEN(F11) -> 42 | H11: Nutrifit | I11: ACCESSOIRES, SHAKERS | L11: garantie | M11: No variations found | N11: Yes | O11: Instagram link in body; ALL CAPS name
A12: 10022 | B12: simple | C12: ZINC BISGLICINATE 90 CAP | D12: Zinc bisglycinate 90 gélules – Applied Nutrition | E12: =LEN(D12) -> 48 | F12: Zinc bisglycinate 90 gélules – Applied Nutrition | G12: =LEN(F12) -> 48 | H12: Applied Nutrition | I12: NOS BEST-SELLERS, SOMMEIL, VITAMINES - MINÉRAUX | L12: hormon, immunitaire, testostérone | M12: OK | N12: Yes | O12: H1 inside description; Instagram link in body; Pasted HTML junk; ALL CAPS name
A13: 10083 | B13: simple | C13: NF GOURDE 600ML | D13: Gourde NF 600 ml – Nutrifit | E13: =LEN(D13) -> 27 | F13: Gourde NF 600 ml – Nutrifit | Nutrifitness | G13: =LEN(F13) -> 42 | H13: Nutrifit | I13: ACCESSOIRES | M13: Missing | N13: Yes | O13: Instagram link in body; ALL CAPS name
A14: 11236 | B14: simple | C14: PROTÉINE VEGAN RIZ BRUN BIO 500G | D14: Protéine végétale de riz brun bio 500 g – Bioyos | E14: =LEN(D14) -> 48 | F14: Protéine végétale de riz brun bio 500 g – Bioyos | G14: =LEN(F14) -> 48 | H14: Bioyos | I14: NOS BEST-SELLERS, PROTÉINES, COMPLÉMENTS > PROTÉINES & GAINERS | L14: maigr | M14: OK | N14: Yes | O14: Instagram link in body; ALL CAPS name
A15: 11269 | B15: variable | C15: BIG LEAN MASS GAINER | D15: Big Lean Mass Gainer – Marvelous | E15: =LEN(D15) -> 32 | F15: Big Lean Mass Gainer – Marvelous | Nutrifitness | G15: =LEN(F15) -> 47 | H15: Marvelous | I15: PRENDRE DU MUSCLE, PROTÉINES | M15: OK (all variations) | N15: Yes | O15: Instagram link in body; Pasted HTML junk; ALL CAPS name
A16: 11296 | B16: variable | C16: HYPE AMINO 270G | D16: Hype Amino 270 g – Marvelous | E16: =LEN(D16) -> 28 | F16: Hype Amino 270 g – Marvelous | Nutrifitness | G16: =LEN(F16) -> 43 | H16: Marvelous | I16: BCAA, PENDANT SPORT | M16: No variations found | N16: Yes | O16: Instagram link in body; ALL CAPS name
A17: 11328 | B17: simple | C17: POUDRE DE COLLAGENE MIX GOÛT MANGUE 300G | D17: Collagène en poudre goût mangue 300 g – Marvelous | E17: =LEN(D17) -> 49 | F17: Collagène en poudre goût mangue 300 g – Marvelous | G17: =LEN(F17) -> 49 | H17: Marvelous | I17: NOS BEST-SELLERS, PEAU - ARTICULATIONS | M17: OK | N17: Yes | O17: Instagram link in body; ALL CAPS name
A18: 11379 | B18: simple | C18: VITAMINE C 1000MG 90 CAPS | D18: Vitamine C 1000 mg – 90 gélules – Marvelous | E18: =LEN(D18) -> 43 | F18: Vitamine C 1000 mg – 90 gélules – Marvelous | Nutrifitness | G18: =LEN(F18) -> 58 | H18: Marvelous | I18: VITAMINES - MINÉRAUX | L18: immunitaire | M18: OK | N18: Yes | O18: Instagram link in body; ALL CAPS name
A19: 11389 | B19: simple | C19: GLICEROL 300G | D19: Glycérol en poudre 300 g – Marvelous | E19: =LEN(D19) -> 36 | F19: Glycérol en poudre 300 g – Marvelous | Nutrifitness | G19: =LEN(F19) -> 51 | H19: Marvelous | I19: PENDANT SPORT | M19: OK | N19: Yes | O19: Instagram link in body; ALL CAPS name
A20: 11648 | B20: simple | C20: BETA-ALANINE EN POUDRE 250G | D20: Bêta-alanine en poudre 250 g – Marvelous | E20: =LEN(D20) -> 40 | F20: Bêta-alanine en poudre 250 g – Marvelous | Nutrifitness | G20: =LEN(F20) -> 55 | H20: Marvelous | I20: AVANT SPORT | M20: OK | N20: No | O20: Unpublished; Instagram link in body; ALL CAPS name
A21: 11806 | B21: simple | C21: OMEGA 3 - 120 SOFTGELS | D21: Oméga 3 – 120 softgels – Marvelous | E21: =LEN(D21) -> 34 | F21: Oméga 3 – 120 softgels – Marvelous | Nutrifitness | G21: =LEN(F21) -> 49 | H21: Marvelous | I21: VITAMINES - MINÉRAUX | L21: cholestérol, soigne | M21: OK | N21: Yes | O21: ALL CAPS name
A22: 12578 | B22: variable | C22: ABE ULTIMATE PRE WORKOUT 315G | D22: ABE Ultimate Pre-Workout 315 g – Applied Nutrition | E22: =LEN(D22) -> 50 | F22: ABE Ultimate Pre-Workout 315 g – Applied Nutrition | G22: =LEN(F22) -> 50 | H22: Applied Nutrition | I22: AVANT SPORT | L22: garantie, soigne | M22: OK (all variations) | N22: No | O22: Unpublished; H1 inside description; Instagram link in body; Pasted HTML junk; ALL CAPS name
A23: 12650 | B23: variable | C23: ISO WHEY ZERO 907G | D23: Iso Whey Zero 907 g – Bigman | E23: =LEN(D23) -> 28 | F23: Iso Whey Zero 907 g – Bigman | Nutrifitness | G23: =LEN(F23) -> 43 | H23: Bigman | I23: NOS BEST-SELLERS, PROTÉINES, COMPLÉMENTS > PROTÉINES & GAINERS | M23: OK (all variations) | N23: Yes | O23: ALL CAPS name
A24: 12855 | B24: simple | C24: L-ACETIL CARNITINE 60 CAPS | D24: L-acétyl-carnitine 60 gélules – Pronutrition | E24: =LEN(D24) -> 44 | F24: L-acétyl-carnitine 60 gélules – Pronutrition | Nutrifitness | G24: =LEN(F24) -> 59 | H24: Pronutrition | I24: AVANT SPORT, NOS BEST-SELLERS, PERTE DE POIDS, COMPLÉMENTS > PERTE DE POIDS & MÉTABOLISME | L24: brûle | M24: OK | N24: Yes | O24: Instagram link in body; ALL CAPS name
A25: 12867 | B25: variable | C25: FARINE DE RIZ 1.5KG | D25: Farine de riz 1,5 kg – Bigman | E25: =LEN(D25) -> 29 | F25: Farine de riz 1,5 kg – Bigman | Nutrifitness | G25: =LEN(F25) -> 44 | H25: Bigman | I25: GLUCIDES | M25: OK (all variations) | N25: Yes | O25: ALL CAPS name
A26: 12882 | B26: variable | C26: CRÈME À TARTINER 350G | D26: Crème à tartiner 350 g – Pronutrition | E26: =LEN(D26) -> 37 | F26: Crème à tartiner 350 g – Pronutrition | Nutrifitness | G26: =LEN(F26) -> 52 | H26: Pronutrition | I26: NOS BEST-SELLERS, SNACKS | M26: OK (all variations) | N26: Yes | O26: Instagram link in body; ALL CAPS name
A27: 12902 | B27: simple | C27: GLUTATHION LIPOSOMALE 30 CAPS | D27: Glutathion liposomal 30 gélules – Pronutrition | E27: =LEN(D27) -> 46 | F27: Glutathion liposomal 30 gélules – Pronutrition | G27: =LEN(F27) -> 46 | H27: Pronutrition | I27: ANTIOXYDANTS, VITAMINES - MINÉRAUX | L27: détox, immunitaire | M27: OK | N27: Yes | O27: Instagram link in body; ALL CAPS name
A28: 12913 | B28: variable | C28: FARINE DE PATATE DOUCE | D28: Farine de patate douce – Ingredients | E28: =LEN(D28) -> 36 | F28: Farine de patate douce – Ingredients | Nutrifitness | G28: =LEN(F28) -> 51 | H28: Ingredients | I28: GLUCIDES, SHAKERS | J28: Listed under SHAKERS – move to GLUCIDES only | M28: OK (all variations) | N28: Yes | O28: Instagram link in body; ALL CAPS name
A29: 12992 | B29: simple | C29: ZMA 90 CAPS | D29: ZMA 90 gélules – Marvelous | E29: =LEN(D29) -> 26 | F29: ZMA 90 gélules – Marvelous | Nutrifitness | G29: =LEN(F29) -> 41 | H29: Marvelous | I29: ÉNERGIE - RÉCUPÉRATION, SOMMEIL, VITAMINES - MINÉRAUX | L29: hormon, immunitaire, testostérone | M29: OK | N29: Yes | O29: Instagram link in body; ALL CAPS name
A30: 13016 | B30: variable | C30: HYDRA - ELECTROLYTES 210G | D30: Hydra Électrolytes 210 g – Per4m | E30: =LEN(D30) -> 32 | F30: Hydra Électrolytes 210 g – Per4m | Nutrifitness | G30: =LEN(F30) -> 47 | H30: Per4m | I30: APRES SPORT, PENDANT SPORT | M30: OK (all variations) | N30: Yes | O30: Instagram link in body; ALL CAPS name
A31: 13035 | B31: simple | C31: MAGNÉSIUM BISGLYCINATE 180G LEMON | D31: Magnésium bisglycinate citron 180 g – Pronutrition | E31: =LEN(D31) -> 50 | F31: Magnésium bisglycinate citron 180 g – Pronutrition | G31: =LEN(F31) -> 50 | H31: Pronutrition | I31: ÉNERGIE - RÉCUPÉRATION, NOS BEST-SELLERS, SOMMEIL, VITAMINES - MINÉRAUX | L31: anxiété, tension | M31: OK | N31: Yes | O31: Instagram link in body; ALL CAPS name
A32: 13708 | B32: simple | C32: CALCIUM 120 TABS | D32: Calcium 120 comprimés – Pronutrition | E32: =LEN(D32) -> 36 | F32: Calcium 120 comprimés – Pronutrition | Nutrifitness | G32: =LEN(F32) -> 51 | H32: Pronutrition | I32: VITAMINES - MINÉRAUX | M32: OK | N32: Yes | O32: Instagram link in body; ALL CAPS name
A33: 13868 | B33: simple | C33: GLUTAMINE BIGMAN KYOWA 300G | D33: Glutamine Kyowa 300 g – Bigman | E33: =LEN(D33) -> 30 | F33: Glutamine Kyowa 300 g – Bigman | Nutrifitness | G33: =LEN(F33) -> 45 | H33: Bigman | I33: APRES SPORT, DIGESTION | L33: garantie | M33: OK | N33: Yes | O33: Instagram link in body; ALL CAPS name
A34: 13873 | B34: simple | C34: CREAPURE BIGMAN 300G | D34: Créatine Creapure® 300 g – Bigman | E34: =LEN(D34) -> 33 | F34: Créatine Creapure® 300 g – Bigman | Nutrifitness | G34: =LEN(F34) -> 48 | H34: Bigman | I34: APRES SPORT, CRÉATINE | M34: OK | N34: Yes | O34: Instagram link in body; ALL CAPS name
A35: 13972 | B35: simple | C35: 20 SACHETS ENERDYN ORANGE | D35: Enerdyn Orange – 20 sachets – Pronutrition | E35: =LEN(D35) -> 42 | F35: Enerdyn Orange – 20 sachets – Pronutrition | Nutrifitness | G35: =LEN(F35) -> 57 | H35: Pronutrition | I35: APRES SPORT, CRÉATINE | J35: Listed under CRÉATINE – confirm real product type | M35: OK | N35: Yes | O35: Instagram link in body; ALL CAPS name
A36: 13985 | B36: variable | C36: FURIUX GAINER 3KG | D36: Furiux Gainer 3 kg – Bigman | E36: =LEN(D36) -> 27 | F36: Furiux Gainer 3 kg – Bigman | Nutrifitness | G36: =LEN(F36) -> 42 | H36: Bigman | I36: PRENDRE DU MUSCLE, COMPLÉMENTS > PROTÉINES & GAINERS, SHAKERS | J36: Listed under SHAKERS – move to PRENDRE DU MUSCLE / GAINERS only | M36: OK (all variations) | N36: Yes | O36: Instagram link in body; ALL CAPS name
A37: 14057 | B37: variable | C37: AUKAN PRE WORKOUT 300G | D37: Aukan Pre-Workout 300 g – Bigman | E37: =LEN(D37) -> 32 | F37: Aukan Pre-Workout 300 g – Bigman | Nutrifitness | G37: =LEN(F37) -> 47 | H37: Bigman | I37: AVANT SPORT, NOS BEST-SELLERS | M37: OK (all variations) | N37: No | O37: Unpublished; Instagram link in body; ALL CAPS name
A38: 14215 | B38: variable | C38: BM EAA 300G | D38: BM EAA 300 g – Bigman | E38: =LEN(D38) -> 21 | F38: BM EAA 300 g – Bigman | Nutrifitness | G38: =LEN(F38) -> 36 | H38: Bigman | I38: BCAA, NOS BEST-SELLERS, PENDANT SPORT | L38: immunitaire | M38: OK (all variations) | N38: Yes | O38: ALL CAPS name
A39: 14309 | B39: variable | C39: ULTIMATE WHEY BIGMAN 2KG | D39: Ultimate Whey 2 kg – Bigman | E39: =LEN(D39) -> 27 | F39: Ultimate Whey 2 kg – Bigman | Nutrifitness | G39: =LEN(F39) -> 42 | H39: Bigman | I39: NOS BEST-SELLERS, PROTÉINES, COMPLÉMENTS > PROTÉINES & GAINERS | L39: rétention d | M39: OK (all variations) | N39: Yes | O39: Instagram link in body; ALL CAPS name
A40: 14341 | B40: variable | C40: ISO BULK WHEY BIOLOGIQUE | D40: Iso Bulk Whey biologique – Marvelous | E40: =LEN(D40) -> 36 | F40: Iso Bulk Whey biologique – Marvelous | Nutrifitness | G40: =LEN(F40) -> 51 | H40: Marvelous | I40: NOS BEST-SELLERS, PROTÉINES, COMPLÉMENTS > PROTÉINES & GAINERS | M40: 2 of 5 variations missing | N40: Yes | O40: Instagram link in body; ALL CAPS name
...

Sheet Pilot rewrites
A1: Field | B1: Product 1 – ID 25611 (Applied Nutrition) | C1: Product 2 – ID 9526 (Marvelous)
A2: Current name | B2: APPLIED CREATINE MONOHYDRATE 250G | C2: CREATINE EN POUDRE 300G
A3: NEW name | B3: Créatine monohydrate 250 g – Applied Nutrition | C3: Créatine 200 mesh en poudre 300 g – Marvelous
A4: New short description | B4: Créatine monohydrate micronisée à 100 %, en pot de 250 g (50 portions de 5 g). Une poudre simple, sans autre ingrédient, pour les sportifs en musculation et en efforts intenses et répétés. Se mélange à l'eau ou au shaker. Testée dans le cadre du programme Informed Sport. | C4: Créatine en poudre 200 mesh (particules très fines), pot de 300 g, pour la musculation et les sports de force. Dose d'usage : 5 g par jour, à mélanger à la boisson de votre choix. [À VÉRIFIER : forme de créatine et nombre de portions sur l'étiquette]
A5: Meta title | B5: Créatine monohydrate 250 g – Applied Nutrition | C5: Créatine 200 mesh 300 g – Marvelous | Nutrifitness
A6: Meta description | B6: Créatine monohydrate micronisée Applied Nutrition, 250 g (50 portions de 5 g). Boutique à Genève et livraison dans toute la Suisse. | C6: Créatine en poudre 200 mesh Marvelous, pot de 300 g. Mode d'emploi, conseils et livraison en Suisse. Boutique à Genève.
A7: Image alt text 1 | B7: Pot de créatine monohydrate Applied Nutrition 250 g | C7: Pot de créatine en poudre 200 mesh Marvelous 300 g
A8: Image alt text 2 | B8: Valeurs nutritionnelles de la créatine monohydrate Applied Nutrition 250 g | C8: [À définir selon l'image d'étiquette]
A9: New long description (HTML, no H1) | B9: <h2>Créatine monohydrate Applied Nutrition 250 g : l'essentiel</h2> <p>Cette créatine monohydrate Applied Nutrition est une poudre micronisée composée à 100 % de créatine monohydrate. Elle s'adresse aux sportifs qui pratiquent la musculation ou des efforts courts, intenses et répétés. Le pot de 250 g contient 50 portions de 5 g.</p> <h2>Pour qui ?</h2> <p>Pour les pratiquants de musculation, de sports de force ou d'entraînements par séries courtes et intenses, qui cherchent un complément simple, sans mélange d'ingrédients.</p> <h2>Caractéristiques clés</h2> <ul> <li>100 % créatine monohydrate micronisée, sans autre ingrédient</li> <li>5 g (5 000 mg) de créatine par portion</li> <li>Pot de 250 g = 50 portions</li> <li>Poudre fine qui se mélange facilement à l'eau ou à un shaker</li> <li>Testée dans le cadre du programme Informed Sport</li> </ul> <h2>Conseils d'utilisation</h2> <p>Mélangez 1 mesure de 5 g avec 200 à 300 ml d'eau ou votre boisson préférée. Prenez-la tous les jours, y compris les jours de repos. Vous pouvez aussi l'ajouter à votre shaker de protéines. Respectez les recommandations figurant sur l'emballage.</p> <p>La créatine augmente la performance physique lors d'exercices successifs de courte durée et de haute intensité. L'effet bénéfique est obtenu avec une consommation quotidienne de 3 g.</p> <h2>Composition et valeurs nutritionnelles</h2> <table><tr><th>Information</th><th>Par portion</th></tr> <tr><td>Créatine monohydrate</td><td>5 000 mg</td></tr> <tr><td>Taille d'une portion</td><td>5 g</td></tr> <tr><td>Nombre de portions</td><td>50</td></tr> <tr><td>Poids net</td><td>250 g</td></tr></table> <p><strong>Ingrédients :</strong> 100 % créatine monohydrate.<br><strong>Allergènes :</strong> fabriquée dans une installation qui manipule aussi du lait, du soja, des œufs, du poisson, du gluten et leurs dérivés.</p> <p><em>Les compléments alimentaires ne remplacent pas une alimentation variée et équilibrée. En cas de maladie rénale, demandez conseil à votre médecin avant toute supplémentation.</em></p> <h2>Acheter chez Nutrifitness</h2> <p>Disponible dans notre boutique de Genève et en livraison dans toute la Suisse.</p> <h2>Questions fréquentes</h2> <h3>Combien de temps dure un pot de 250 g ?</h3> <p>Avec une portion de 5 g par jour, un pot dure 50 jours.</p> <h3>Faut-il prendre la créatine les jours de repos ?</h3> <p>Oui, la prise quotidienne est recommandée, y compris les jours sans entraînement.</p> <h3>Peut-on la mélanger à sa protéine en poudre ?</h3> <p>Oui, vous pouvez ajouter la mesure de 5 g directement dans votre shaker de protéines ou la diluer dans de l'eau.</p> <h3>Quelle est la différence avec une créatine « 200 mesh » ?</h3> <p>Ici la poudre est micronisée (très fine). Le détail de la finesse n'est pas précisé sur la fiche d'origine : <strong>[À VÉRIFIER avec le fournisseur avant publication]</strong>.</p> | C9: <h2>Créatine 200 mesh en poudre 300 g Marvelous : l'essentiel</h2> <p>La créatine 200 mesh de Marvelous est une poudre à granulométrie très fine : « 200 mesh » désigne des particules généralement inférieures à 74 microns, ce qui facilite le mélange dans une boisson. Pot de 300 g. <strong>[À VÉRIFIER : forme de créatine (monohydrate ?) et nombre de portions sur l'étiquette]</strong></p> <h2>Pour qui ?</h2> <p>Pour les pratiquants de musculation, de sports de force et d'entraînements par séries courtes et intenses.</p> <h2>Caractéristiques clés</h2> <ul> <li>Créatine en poudre 200 mesh (particules très fines)</li> <li>Pot de 300 g</li> <li>Dose d'usage : 5 g par jour (1 mesure)</li> <li>Se mélange à la boisson de votre choix</li> </ul> <h2>Conseils d'utilisation</h2> <p>Prenez 5 g (1 mesure) par jour, de préférence après l'entraînement, avec une source de sucres rapides (banane, miel ou compote de pomme par exemple). Les jours sans entraînement, prenez 5 g le matin dans un jus de fruit pour garder un apport régulier.</p> <p>La créatine augmente la performance physique lors d'exercices successifs de courte durée et de haute intensité. L'effet bénéfique est obtenu avec une consommation quotidienne de 3 g. <strong>[Formulation à faire valider par le client selon la réglementation suisse]</strong></p> <h2>Composition et valeurs nutritionnelles</h2> <p><strong>[À COMPLÉTER depuis l'étiquette : ingrédients, valeurs par portion, taille de portion, allergènes, pays de fabrication]</strong></p> <p><em>Les compléments alimentaires ne remplacent pas une alimentation variée et équilibrée. En cas de maladie rénale, demandez conseil à votre médecin avant toute supplémentation.</em></p> <h2>Acheter chez Nutrifitness</h2> <p>Disponible dans notre boutique de Genève et en livraison dans toute la Suisse.</p> <h2>Questions fréquentes</h2> <h3>Que veut dire « 200 mesh » ?</h3> <p>Le maillage 200 correspond à des particules très petites, généralement inférieures à 74 microns. La poudre est donc fine et se dilue facilement.</p> <h3>Quand prendre la créatine ?</h3> <p>De préférence après l'entraînement, avec des sucres rapides. Les jours de repos, 5 g le matin dans un jus de fruit.</p> <h3>Combien de temps dure un pot de 300 g ?</h3> <p>Avec 5 g par jour : 60 jours. <strong>[À VÉRIFIER avec la taille de portion de l'étiquette]</strong></p>
A10: What was wrong before | B10: H1 inside the description with pasted-editor CSS classes; product name repeated in ALL CAPS; no FAQ; no usage-by-day detail structure; brand not in the name format used by Google Shopping. | C10: Medical claims about Alzheimer's and Parkinson's; "jusqu'à 10 %" strength-gain claim; cognitive, hydration, "récupération rapide" claims; H1 in body; Instagram link as anchor; no nutrition table, ingredients, allergens or servings.
A11: Claims removed / review | B11: None removed. The creatine performance wording is kept because it was already on the current page; client to confirm it is allowed for Swiss food labelling. | C11: REMOVED: Alzheimer/Parkinson benefits, "gain de force jusqu'à 10 %", cognitive clarity/concentration, "hydratation cellulaire optimale décuple l'endurance", "récupération musculaire rapide". Replaced with one standard creatine performance sentence, flagged for client validation.
